<?xml version="1.0" encoding="utf-8"?>
<!-- =================================================================================== -->
<!-- |    This document was autogenerated by xacro from urdf_xacro/sekirei2020_gazebo.urdf.xacro | -->
<!-- |    EDITING THIS FILE BY HAND IS NOT RECOMMENDED                                 | -->
<!-- =================================================================================== -->
<robot name="sekirei2020">
  <!-- include -->
  <!--                                                                                       -->
  <!-- macros for making track                                                               -->
  <!--     * useful when difining entities for ContinuousTrack plugin                        -->
  <!--     * see gazebo_continuous_track_example/urdf/example_track.urdf.xacro to know usage -->
  <!--                                                                                       -->
  <!-- macros which expand to inertial/collision/visual -->
  <!-- macros which expand to box/polyline collision and visual. convenient when defining pattern elements on a track -->
  <!-- macros for populating general links/joints -->
  <!-- track segment templates which can be used with above population macros -->
  <!-- macros for populating track segments with above population macros and above templates -->
  <!-- macro which expands to plugin definition -->
  <!-- main entry point: macro for making oval track by ContinuousTrack plugin -->
  <!--                                                                                              -->
  <!-- macros for making simple track                                                               -->
  <!--     * useful when difining entities for ContinuousTrackSimple plugin                         -->
  <!--     * see gazebo_continuous_track_example/urdf/example_track_simple.urdf.xacro to know usage -->
  <!--                                                                                              -->
  <!-- macros which expand to inertial/collision/visual -->
  <!-- macros which expand to box/polyline collision and visual. convenient when defining pattern elements on a track -->
  <!-- macros for populating general links/joints -->
  <!-- track segment templates which can be used with above population macros -->
  <!-- macros for populating track segments with above population macros and above templates -->
  <!-- macro which expands to simple plugin definition -->
  <!-- main entry point: macro for making oval track by ContinuousTrackSimple plugin -->
  <!-- macro -->
  <!-- belt for crawler and flipper -->
  <!-- devices -->
  <!-- URDF -->
  <!-- This file is for ROS system -->
  <!-- include macros -->
  <!-- component macro -->
  <!-- component macro -->
  <!-- macro -->
  <!-- URDF -->
  <link name="center_unit">
    <inertial>
      <mass value="10.0"/>
      <inertia ixx="0.0317708333333" ixy="0" ixz="0" iyy="0.214914166667" iyz="0" izz="0.226883333333"/>
    </inertial>
    <visual>
      <geometry>
        <box size="0.496 0.162 0.109"/>
      </geometry>
    </visual>
    <collision>
      <geometry>
        <box size="0.496 0.162 0.109"/>
      </geometry>
    </collision>
  </link>
  <joint name="joint_of_left_crawler" type="fixed">
    <parent link="center_unit"/>
    <child link="left_crawler_body"/>
    <origin rpy="0 0 0" xyz="0.0 0.081 -0.0155"/>
  </joint>
  <joint name="joint_of_right_crawler" type="fixed">
    <parent link="center_unit"/>
    <child link="right_crawler_body"/>
    <origin rpy="0 0 0" xyz="0.0 -0.081 -0.0155"/>
  </joint>
  <link name="left_crawler_body">
    <inertial>
      <mass value="1.68"/>
      <inertia ixx="0.0034048224" ixy="0" ixz="0" iyy="0.0128002574" iyz="0" izz="0.013427435"/>
    </inertial>
    <visual>
      <origin rpy="0 0 0" xyz="0 0.065 0"/>
      <geometry>
        <box size="0.2855 0.13 0.0996"/>
      </geometry>
    </visual>
    <collision>
      <origin rpy="0 0 0" xyz="0 0.065 0"/>
      <geometry>
        <box size="0.2955 0.12 0.0996"/>
      </geometry>
    </collision>
  </link>
  <link name="left_crawler_sprocket">
    <inertial>
      <mass value="0.36"/>
      <!-- assuming axis of cylinder is y, not z -->
      <inertia ixx="0.0006552036" ixy="0" ixz="0" iyy="0.0004464072" iyz="0" izz="0.0006552036"/>
    </inertial>
    <visual>
      <origin rpy="1.57079632679 0 0" xyz="0 0 0"/>
      <geometry>
        <cylinder length="0.13" radius="0.0498"/>
      </geometry>
    </visual>
    <visual>
      <origin rpy="0 0 0" xyz="0 0 0"/>
      <geometry>
        <box size="0.01 0.13 0.1201425"/>
      </geometry>
    </visual>
    <visual>
      <origin rpy="0 0 0" xyz="0 0 0"/>
      <geometry>
        <box size="0.1201425 0.13 0.01"/>
      </geometry>
    </visual>
    <collision>
      <origin rpy="1.57079632679 0 0" xyz="0 0 0"/>
      <geometry>
        <cylinder length="0.12" radius="0.0498"/>
      </geometry>
    </collision>
  </link>
  <joint name="left_crawler_sprocket_axle" type="continuous">
    <origin rpy="0 0 0" xyz="0.205 0.065 0"/>
    <parent link="left_crawler_body"/>
    <child link="left_crawler_sprocket"/>
    <axis xyz="0 1 0"/>
  </joint>
  <transmission name="left_crawler_sprocket_transmission">
    <type>transmission_interface/SimpleTransmission</type>
    <joint name="left_crawler_sprocket_axle">
      <hardwareInterface>hardware_interface/VelocityJointInterface</hardwareInterface>
    </joint>
    <actuator name="left_crawler_sprocket_actuator">
      <mechanicalReduction>1</mechanicalReduction>
    </actuator>
  </transmission>
  <!-- idler on the other side of the sprocket -->
  <link name="left_crawler_idler">
    <inertial>
      <mass value="0.36"/>
      <!-- assuming axis of cylinder is y, not z -->
      <inertia ixx="0.0006552036" ixy="0" ixz="0" iyy="0.0004464072" iyz="0" izz="0.0006552036"/>
    </inertial>
    <visual>
      <origin rpy="1.57079632679 0 0" xyz="0 0 0"/>
      <geometry>
        <cylinder length="0.13" radius="0.0498"/>
      </geometry>
    </visual>
    <collision>
      <origin rpy="1.57079632679 0 0" xyz="0 0 0"/>
      <geometry>
        <cylinder length="0.12" radius="0.0498"/>
      </geometry>
    </collision>
  </link>
  <joint name="left_crawler_idler_axle" type="fixed">
    <origin rpy="0 0 0" xyz="-0.205 0.065 0"/>
    <parent link="left_crawler_body"/>
    <child link="left_crawler_idler"/>
    <limit effort="100" velocity="100"/>
  </joint>
  <link name="right_crawler_body">
    <inertial>
      <mass value="1.68"/>
      <inertia ixx="0.0034048224" ixy="0" ixz="0" iyy="0.0128002574" iyz="0" izz="0.013427435"/>
    </inertial>
    <visual>
      <origin rpy="0 0 0" xyz="0 -0.065 0"/>
      <geometry>
        <box size="0.2855 0.13 0.0996"/>
      </geometry>
    </visual>
    <collision>
      <origin rpy="0 0 0" xyz="0 -0.065 0"/>
      <geometry>
        <box size="0.2955 0.12 0.0996"/>
      </geometry>
    </collision>
  </link>
  <link name="right_crawler_sprocket">
    <inertial>
      <mass value="0.36"/>
      <!-- assuming axis of cylinder is y, not z -->
      <inertia ixx="0.0006552036" ixy="0" ixz="0" iyy="0.0004464072" iyz="0" izz="0.0006552036"/>
    </inertial>
    <visual>
      <origin rpy="1.57079632679 0 0" xyz="0 0 0"/>
      <geometry>
        <cylinder length="0.13" radius="0.0498"/>
      </geometry>
    </visual>
    <visual>
      <origin rpy="0 0 0" xyz="0 0 0"/>
      <geometry>
        <box size="0.01 0.13 0.1201425"/>
      </geometry>
    </visual>
    <visual>
      <origin rpy="0 0 0" xyz="0 0 0"/>
      <geometry>
        <box size="0.1201425 0.13 0.01"/>
      </geometry>
    </visual>
    <collision>
      <origin rpy="1.57079632679 0 0" xyz="0 0 0"/>
      <geometry>
        <cylinder length="0.12" radius="0.0498"/>
      </geometry>
    </collision>
  </link>
  <joint name="right_crawler_sprocket_axle" type="continuous">
    <origin rpy="0 0 0" xyz="0.205 -0.065 0"/>
    <parent link="right_crawler_body"/>
    <child link="right_crawler_sprocket"/>
    <axis xyz="0 1 0"/>
  </joint>
  <transmission name="right_crawler_sprocket_transmission">
    <type>transmission_interface/SimpleTransmission</type>
    <joint name="right_crawler_sprocket_axle">
      <hardwareInterface>hardware_interface/VelocityJointInterface</hardwareInterface>
    </joint>
    <actuator name="right_crawler_sprocket_actuator">
      <mechanicalReduction>1</mechanicalReduction>
    </actuator>
  </transmission>
  <!-- idler on the other side of the sprocket -->
  <link name="right_crawler_idler">
    <inertial>
      <mass value="0.36"/>
      <!-- assuming axis of cylinder is y, not z -->
      <inertia ixx="0.0006552036" ixy="0" ixz="0" iyy="0.0004464072" iyz="0" izz="0.0006552036"/>
    </inertial>
    <visual>
      <origin rpy="1.57079632679 0 0" xyz="0 0 0"/>
      <geometry>
        <cylinder length="0.13" radius="0.0498"/>
      </geometry>
    </visual>
    <collision>
      <origin rpy="1.57079632679 0 0" xyz="0 0 0"/>
      <geometry>
        <cylinder length="0.12" radius="0.0498"/>
      </geometry>
    </collision>
  </link>
  <joint name="right_crawler_idler_axle" type="fixed">
    <origin rpy="0 0 0" xyz="-0.205 -0.065 0"/>
    <parent link="right_crawler_body"/>
    <child link="right_crawler_idler"/>
    <limit effort="100" velocity="100"/>
  </joint>
  <joint name="joint_of_front_left_flipper" type="revolute">
    <parent link="left_crawler_body"/>
    <child link="front_left_flipper_body"/>
    <origin rpy="0 0 0" xyz="0.205 0.162 0"/>
    <axis xyz="0 1 0"/>
    <limit effort="25" lower="-3.14" upper="3.14" velocity="1"/>
    <dynamics damping="0.5"/>
  </joint>
  <transmission name="transmission_of_front_left_flipper">
    <type>transmission_interface/SimpleTransmission</type>
    <joint name="joint_of_front_left_flipper">
      <hardwareInterface>hardware_interface/EffortJointInterface</hardwareInterface>
    </joint>
    <actuator name="motor_of_front_left_flipper">
      <hardwareInterface>hardware_interface/EffortJointInterface</hardwareInterface>
      <mechanismReduction>1</mechanismReduction>
    </actuator>
  </transmission>
  <joint name="joint_of_front_right_flipper" type="revolute">
    <parent link="right_crawler_body"/>
    <child link="front_right_flipper_body"/>
    <origin rpy="0 0 0" xyz="0.205 -0.162 0"/>
    <axis xyz="0 1 0"/>
    <limit effort="25" lower="-3.14" upper="3.14" velocity="1"/>
    <dynamics damping="0.5"/>
  </joint>
  <transmission name="transmission_of_front_right_flipper">
    <type>transmission_interface/SimpleTransmission</type>
    <joint name="joint_of_front_right_flipper">
      <hardwareInterface>hardware_interface/EffortJointInterface</hardwareInterface>
    </joint>
    <actuator name="motor_of_front_right_flipper">
      <hardwareInterface>hardware_interface/EffortJointInterface</hardwareInterface>
      <mechanismReduction>1</mechanismReduction>
    </actuator>
  </transmission>
  <joint name="joint_of_rear_left_flipper" type="revolute">
    <parent link="left_crawler_body"/>
    <child link="rear_left_flipper_body"/>
    <origin rpy="0 0 0" xyz="-0.205 0.162 0"/>
    <axis xyz="0 1 0"/>
    <limit effort="25" lower="-3.14" upper="3.14" velocity="1"/>
    <dynamics damping="0.5"/>
  </joint>
  <transmission name="transmission_of_rear_left_flipper">
    <type>transmission_interface/SimpleTransmission</type>
    <joint name="joint_of_rear_left_flipper">
      <hardwareInterface>hardware_interface/EffortJointInterface</hardwareInterface>
    </joint>
    <actuator name="motor_of_rear_left_flipper">
      <hardwareInterface>hardware_interface/EffortJointInterface</hardwareInterface>
      <mechanismReduction>1</mechanismReduction>
    </actuator>
  </transmission>
  <joint name="joint_of_rear_right_flipper" type="revolute">
    <parent link="right_crawler_body"/>
    <child link="rear_right_flipper_body"/>
    <origin rpy="0 0 0" xyz="-0.205 -0.162 0"/>
    <axis xyz="0 1 0"/>
    <limit effort="25" lower="-3.14" upper="3.14" velocity="1"/>
    <dynamics damping="0.5"/>
  </joint>
  <transmission name="transmission_of_rear_right_flipper">
    <type>transmission_interface/SimpleTransmission</type>
    <joint name="joint_of_rear_right_flipper">
      <hardwareInterface>hardware_interface/EffortJointInterface</hardwareInterface>
    </joint>
    <actuator name="motor_of_rear_right_flipper">
      <hardwareInterface>hardware_interface/EffortJointInterface</hardwareInterface>
      <mechanismReduction>1</mechanismReduction>
    </actuator>
  </transmission>
  <link name="front_left_flipper_body">
    <inertial>
      <mass value="0.56"/>
      <inertia ixx="0.000460984234667" ixy="0" ixz="0" iyy="0.00104604311933" iyz="0" izz="0.000857218884667"/>
    </inertial>
    <visual>
      <origin rpy="0 0 0" xyz="0.114305 0 0"/>
      <geometry>
        <box size="0.12431 0.064 0.08344"/>
      </geometry>
    </visual>
    <collision>
      <origin rpy="0 0 0" xyz="0.114305 0 0"/>
      <geometry>
        <box size="0.13431 0.054 0.08344"/>
      </geometry>
    </collision>
  </link>
  <link name="front_left_flipper_sprocket">
    <inertial>
      <mass value="0.12"/>
      <!-- assuming axis of cylinder is y, not z -->
      <inertia ixx="8.1376752e-05" ixy="0" ixz="0" iyy="0.000104433504" iyz="0" izz="8.1376752e-05"/>
    </inertial>
    <visual>
      <origin rpy="1.57079632679 0 0" xyz="0 0 0"/>
      <geometry>
        <cylinder length="0.064" radius="0.04172"/>
      </geometry>
    </visual>
    <visual>
      <origin rpy="0 0 0" xyz="0 0 0"/>
      <geometry>
        <box size="0.01 0.064 0.1006495"/>
      </geometry>
    </visual>
    <visual>
      <origin rpy="0 0 0" xyz="0 0 0"/>
      <geometry>
        <box size="0.1006495 0.064 0.01"/>
      </geometry>
    </visual>
    <collision>
      <origin rpy="1.57079632679 0 0" xyz="0 0 0"/>
      <geometry>
        <cylinder length="0.054" radius="0.04172"/>
      </geometry>
    </collision>
  </link>
  <joint name="front_left_flipper_sprocket_axle" type="continuous">
    <origin rpy="0 0 0" xyz="0.22861 0 0"/>
    <parent link="front_left_flipper_body"/>
    <child link="front_left_flipper_sprocket"/>
    <axis xyz="0 1 0"/>
  </joint>
  <transmission name="front_left_flipper_sprocket_transmission">
    <type>transmission_interface/SimpleTransmission</type>
    <joint name="front_left_flipper_sprocket_axle">
      <hardwareInterface>hardware_interface/VelocityJointInterface</hardwareInterface>
    </joint>
    <actuator name="front_left_flipper_sprocket_actuator">
      <mechanicalReduction>1</mechanicalReduction>
    </actuator>
  </transmission>
  <!-- idler on the other side of the sprocket -->
  <link name="front_left_flipper_idler">
    <inertial>
      <mass value="0.12"/>
      <!-- assuming axis of cylinder is y, not z -->
      <inertia ixx="8.1376752e-05" ixy="0" ixz="0" iyy="0.000104433504" iyz="0" izz="8.1376752e-05"/>
    </inertial>
    <visual>
      <origin rpy="1.57079632679 0 0" xyz="0 0 0"/>
      <geometry>
        <cylinder length="0.064" radius="0.04172"/>
      </geometry>
    </visual>
    <collision>
      <origin rpy="1.57079632679 0 0" xyz="0 0 0"/>
      <geometry>
        <cylinder length="0.054" radius="0.04172"/>
      </geometry>
    </collision>
  </link>
  <joint name="front_left_flipper_idler_axle" type="fixed">
    <origin rpy="0 0 0" xyz="0.0 0 0"/>
    <parent link="front_left_flipper_body"/>
    <child link="front_left_flipper_idler"/>
    <limit effort="100" velocity="100"/>
  </joint>
  <link name="front_right_flipper_body">
    <inertial>
      <mass value="0.56"/>
      <inertia ixx="0.000460984234667" ixy="0" ixz="0" iyy="0.00104604311933" iyz="0" izz="0.000857218884667"/>
    </inertial>
    <visual>
      <origin rpy="0 0 0" xyz="0.114305 0 0"/>
      <geometry>
        <box size="0.12431 0.064 0.08344"/>
      </geometry>
    </visual>
    <collision>
      <origin rpy="0 0 0" xyz="0.114305 0 0"/>
      <geometry>
        <box size="0.13431 0.054 0.08344"/>
      </geometry>
    </collision>
  </link>
  <link name="front_right_flipper_sprocket">
    <inertial>
      <mass value="0.12"/>
      <!-- assuming axis of cylinder is y, not z -->
      <inertia ixx="8.1376752e-05" ixy="0" ixz="0" iyy="0.000104433504" iyz="0" izz="8.1376752e-05"/>
    </inertial>
    <visual>
      <origin rpy="1.57079632679 0 0" xyz="0 0 0"/>
      <geometry>
        <cylinder length="0.064" radius="0.04172"/>
      </geometry>
    </visual>
    <visual>
      <origin rpy="0 0 0" xyz="0 0 0"/>
      <geometry>
        <box size="0.01 0.064 0.1006495"/>
      </geometry>
    </visual>
    <visual>
      <origin rpy="0 0 0" xyz="0 0 0"/>
      <geometry>
        <box size="0.1006495 0.064 0.01"/>
      </geometry>
    </visual>
    <collision>
      <origin rpy="1.57079632679 0 0" xyz="0 0 0"/>
      <geometry>
        <cylinder length="0.054" radius="0.04172"/>
      </geometry>
    </collision>
  </link>
  <joint name="front_right_flipper_sprocket_axle" type="continuous">
    <origin rpy="0 0 0" xyz="0.22861 0 0"/>
    <parent link="front_right_flipper_body"/>
    <child link="front_right_flipper_sprocket"/>
    <axis xyz="0 1 0"/>
  </joint>
  <transmission name="front_right_flipper_sprocket_transmission">
    <type>transmission_interface/SimpleTransmission</type>
    <joint name="front_right_flipper_sprocket_axle">
      <hardwareInterface>hardware_interface/VelocityJointInterface</hardwareInterface>
    </joint>
    <actuator name="front_right_flipper_sprocket_actuator">
      <mechanicalReduction>1</mechanicalReduction>
    </actuator>
  </transmission>
  <!-- idler on the other side of the sprocket -->
  <link name="front_right_flipper_idler">
    <inertial>
      <mass value="0.12"/>
      <!-- assuming axis of cylinder is y, not z -->
      <inertia ixx="8.1376752e-05" ixy="0" ixz="0" iyy="0.000104433504" iyz="0" izz="8.1376752e-05"/>
    </inertial>
    <visual>
      <origin rpy="1.57079632679 0 0" xyz="0 0 0"/>
      <geometry>
        <cylinder length="0.064" radius="0.04172"/>
      </geometry>
    </visual>
    <collision>
      <origin rpy="1.57079632679 0 0" xyz="0 0 0"/>
      <geometry>
        <cylinder length="0.054" radius="0.04172"/>
      </geometry>
    </collision>
  </link>
  <joint name="front_right_flipper_idler_axle" type="fixed">
    <origin rpy="0 0 0" xyz="0.0 0 0"/>
    <parent link="front_right_flipper_body"/>
    <child link="front_right_flipper_idler"/>
    <limit effort="100" velocity="100"/>
  </joint>
  <link name="rear_left_flipper_body">
    <inertial>
      <mass value="0.56"/>
      <inertia ixx="0.000460984234667" ixy="0" ixz="0" iyy="0.00104604311933" iyz="0" izz="0.000857218884667"/>
    </inertial>
    <visual>
      <origin rpy="0 0 0" xyz="-0.114305 0 0"/>
      <geometry>
        <box size="0.12431 0.064 0.08344"/>
      </geometry>
    </visual>
    <collision>
      <origin rpy="0 0 0" xyz="-0.114305 0 0"/>
      <geometry>
        <box size="0.13431 0.054 0.08344"/>
      </geometry>
    </collision>
  </link>
  <link name="rear_left_flipper_sprocket">
    <inertial>
      <mass value="0.12"/>
      <!-- assuming axis of cylinder is y, not z -->
      <inertia ixx="8.1376752e-05" ixy="0" ixz="0" iyy="0.000104433504" iyz="0" izz="8.1376752e-05"/>
    </inertial>
    <visual>
      <origin rpy="1.57079632679 0 0" xyz="0 0 0"/>
      <geometry>
        <cylinder length="0.064" radius="0.04172"/>
      </geometry>
    </visual>
    <visual>
      <origin rpy="0 0 0" xyz="0 0 0"/>
      <geometry>
        <box size="0.01 0.064 0.1006495"/>
      </geometry>
    </visual>
    <visual>
      <origin rpy="0 0 0" xyz="0 0 0"/>
      <geometry>
        <box size="0.1006495 0.064 0.01"/>
      </geometry>
    </visual>
    <collision>
      <origin rpy="1.57079632679 0 0" xyz="0 0 0"/>
      <geometry>
        <cylinder length="0.054" radius="0.04172"/>
      </geometry>
    </collision>
  </link>
  <joint name="rear_left_flipper_sprocket_axle" type="continuous">
    <origin rpy="0 0 0" xyz="0.0 0 0"/>
    <parent link="rear_left_flipper_body"/>
    <child link="rear_left_flipper_sprocket"/>
    <axis xyz="0 1 0"/>
  </joint>
  <transmission name="rear_left_flipper_sprocket_transmission">
    <type>transmission_interface/SimpleTransmission</type>
    <joint name="rear_left_flipper_sprocket_axle">
      <hardwareInterface>hardware_interface/VelocityJointInterface</hardwareInterface>
    </joint>
    <actuator name="rear_left_flipper_sprocket_actuator">
      <mechanicalReduction>1</mechanicalReduction>
    </actuator>
  </transmission>
  <!-- idler on the other side of the sprocket -->
  <link name="rear_left_flipper_idler">
    <inertial>
      <mass value="0.12"/>
      <!-- assuming axis of cylinder is y, not z -->
      <inertia ixx="8.1376752e-05" ixy="0" ixz="0" iyy="0.000104433504" iyz="0" izz="8.1376752e-05"/>
    </inertial>
    <visual>
      <origin rpy="1.57079632679 0 0" xyz="0 0 0"/>
      <geometry>
        <cylinder length="0.064" radius="0.04172"/>
      </geometry>
    </visual>
    <collision>
      <origin rpy="1.57079632679 0 0" xyz="0 0 0"/>
      <geometry>
        <cylinder length="0.054" radius="0.04172"/>
      </geometry>
    </collision>
  </link>
  <joint name="rear_left_flipper_idler_axle" type="fixed">
    <origin rpy="0 0 0" xyz="-0.22861 0 0"/>
    <parent link="rear_left_flipper_body"/>
    <child link="rear_left_flipper_idler"/>
    <limit effort="100" velocity="100"/>
  </joint>
  <link name="rear_right_flipper_body">
    <inertial>
      <mass value="0.56"/>
      <inertia ixx="0.000460984234667" ixy="0" ixz="0" iyy="0.00104604311933" iyz="0" izz="0.000857218884667"/>
    </inertial>
    <visual>
      <origin rpy="0 0 0" xyz="-0.114305 0 0"/>
      <geometry>
        <box size="0.12431 0.064 0.08344"/>
      </geometry>
    </visual>
    <collision>
      <origin rpy="0 0 0" xyz="-0.114305 0 0"/>
      <geometry>
        <box size="0.13431 0.054 0.08344"/>
      </geometry>
    </collision>
  </link>
  <link name="rear_right_flipper_sprocket">
    <inertial>
      <mass value="0.12"/>
      <!-- assuming axis of cylinder is y, not z -->
      <inertia ixx="8.1376752e-05" ixy="0" ixz="0" iyy="0.000104433504" iyz="0" izz="8.1376752e-05"/>
    </inertial>
    <visual>
      <origin rpy="1.57079632679 0 0" xyz="0 0 0"/>
      <geometry>
        <cylinder length="0.064" radius="0.04172"/>
      </geometry>
    </visual>
    <visual>
      <origin rpy="0 0 0" xyz="0 0 0"/>
      <geometry>
        <box size="0.01 0.064 0.1006495"/>
      </geometry>
    </visual>
    <visual>
      <origin rpy="0 0 0" xyz="0 0 0"/>
      <geometry>
        <box size="0.1006495 0.064 0.01"/>
      </geometry>
    </visual>
    <collision>
      <origin rpy="1.57079632679 0 0" xyz="0 0 0"/>
      <geometry>
        <cylinder length="0.054" radius="0.04172"/>
      </geometry>
    </collision>
  </link>
  <joint name="rear_right_flipper_sprocket_axle" type="continuous">
    <origin rpy="0 0 0" xyz="0.0 0 0"/>
    <parent link="rear_right_flipper_body"/>
    <child link="rear_right_flipper_sprocket"/>
    <axis xyz="0 1 0"/>
  </joint>
  <transmission name="rear_right_flipper_sprocket_transmission">
    <type>transmission_interface/SimpleTransmission</type>
    <joint name="rear_right_flipper_sprocket_axle">
      <hardwareInterface>hardware_interface/VelocityJointInterface</hardwareInterface>
    </joint>
    <actuator name="rear_right_flipper_sprocket_actuator">
      <mechanicalReduction>1</mechanicalReduction>
    </actuator>
  </transmission>
  <!-- idler on the other side of the sprocket -->
  <link name="rear_right_flipper_idler">
    <inertial>
      <mass value="0.12"/>
      <!-- assuming axis of cylinder is y, not z -->
      <inertia ixx="8.1376752e-05" ixy="0" ixz="0" iyy="0.000104433504" iyz="0" izz="8.1376752e-05"/>
    </inertial>
    <visual>
      <origin rpy="1.57079632679 0 0" xyz="0 0 0"/>
      <geometry>
        <cylinder length="0.064" radius="0.04172"/>
      </geometry>
    </visual>
    <collision>
      <origin rpy="1.57079632679 0 0" xyz="0 0 0"/>
      <geometry>
        <cylinder length="0.054" radius="0.04172"/>
      </geometry>
    </collision>
  </link>
  <joint name="rear_right_flipper_idler_axle" type="fixed">
    <origin rpy="0 0 0" xyz="-0.22861 0 0"/>
    <parent link="rear_right_flipper_body"/>
    <child link="rear_right_flipper_idler"/>
    <limit effort="100" velocity="100"/>
  </joint>
  <joint name="front_camera_joint" type="fixed">
    <parent link="center_unit"/>
    <child link="front_camera_link"/>
    <origin rpy="-1.57079632679 0 -1.57079632679" xyz="0.248 0 0.109"/>
  </joint>
  <link name="front_camera_link"/>
  <gazebo reference="front_camera_link">
    <sensor name="front_camera" type="camera">
      <update_rate>10.0</update_rate>
      <camera name="front_camera">
        <pose>0 0 0 0 -1.57079632679 1.57079632679</pose>
        <horizontal_fov>1.3962634</horizontal_fov>
        <image>
          <width>1920</width>
          <height>1080</height>
          <format>R8G8B8</format>
        </image>
        <clip>
          <near>0.02</near>
          <far>300</far>
        </clip>
        <noise>
          <type>gaussian</type>
          <mean>0.0</mean>
          <stddev>0.007</stddev>
        </noise>
      </camera>
      <plugin filename="libgazebo_ros_camera.so" name="camera_controller">
        <alwaysOn>true</alwaysOn>
        <updateRate>0.0</updateRate>
        <cameraName>front_camera</cameraName>
        <imageTopicName>image_raw</imageTopicName>
        <cameraInfoTopicName>camera_info</cameraInfoTopicName>
        <frameName>front_camera_link</frameName>
        <hackBaseline>0.0</hackBaseline>
        <distortionK1>0.0</distortionK1>
        <distortionK2>0.0</distortionK2>
        <distortionK3>0.0</distortionK3>
        <distortionT1>0.0</distortionT1>
        <distortionT2>0.0</distortionT2>
      </plugin>
    </sensor>
  </gazebo>
  <joint name="rear_camera_joint" type="fixed">
    <parent link="center_unit"/>
    <child link="rear_camera_link"/>
    <origin rpy="-1.57079632679 0 -1.57079632679" xyz="-0.248 0 0.109"/>
  </joint>
  <link name="rear_camera_link"/>
  <gazebo reference="rear_camera_link">
    <sensor name="rear_camera" type="camera">
      <update_rate>10.0</update_rate>
      <camera name="rear_camera">
        <pose>0 0 0 0 1.57079632679 1.57079632679</pose>
        <horizontal_fov>1.3962634</horizontal_fov>
        <image>
          <width>1920</width>
          <height>1080</height>
          <format>R8G8B8</format>
        </image>
        <clip>
          <near>0.02</near>
          <far>300</far>
        </clip>
        <noise>
          <type>gaussian</type>
          <mean>0.0</mean>
          <stddev>0.007</stddev>
        </noise>
      </camera>
      <plugin filename="libgazebo_ros_camera.so" name="camera_controller">
        <alwaysOn>true</alwaysOn>
        <updateRate>0.0</updateRate>
        <cameraName>rear_camera</cameraName>
        <imageTopicName>image_raw</imageTopicName>
        <cameraInfoTopicName>camera_info</cameraInfoTopicName>
        <frameName>rear_camera_link</frameName>
        <hackBaseline>0.0</hackBaseline>
        <distortionK1>0.0</distortionK1>
        <distortionK2>0.0</distortionK2>
        <distortionK3>0.0</distortionK3>
        <distortionT1>0.0</distortionT1>
        <distortionT2>0.0</distortionT2>
      </plugin>
    </sensor>
  </gazebo>
  <gazebo>
    <link name="left_crawler_track_straight_segment_link0">
      <pose>-0.205 0.146 0.04675 0 0 0</pose>
      <inertial>
        <pose>0.205 0 -0.031125 0 0 0</pose>
        <mass>0.75</mass>
        <inertia>
          <ixx>0.00114219140625</ixx>
          <ixy>0</ixy>
          <ixz>0</ixz>
          <iyy>0.0107484414062</iyy>
          <iyz>0</iyz>
          <izz>0.01140625</izz>
        </inertia>
      </inertial>
      <collision name="collision">
        <pose>0.205 0 -0.031125 0 0 0</pose>
        <geometry>
          <box>
            <size>0.41 0.12 0.06225</size>
          </box>
        </geometry>
        <surface>
          <friction>
            <ode>
              <mu>0.5</mu>
              <mu2>0.5</mu2>
            </ode>
          </friction>
          <contact>
            <ode>
              <min_depth>0.01</min_depth>
            </ode>
          </contact>
        </surface>
      </collision>
      <visual name="visual">
        <pose>0.205 0 -0.031125 0 0 0</pose>
        <geometry>
          <box>
            <size>0.41 0.12 0.06225</size>
          </box>
        </geometry>
        <material>
          <ambient>0.0 0.0 0.0 1</ambient>
          <diffuse>0.0 0.0 0.0 1</diffuse>
          <specular>0.5 0.5 0.5 1</specular>
          <emissive>0 0 0 1</emissive>
        </material>
      </visual>
    </link>
  </gazebo>
  <gazebo>
    <link name="left_crawler_track_straight_segment_link1">
      <pose>0.205 0.146 -0.07775 0 3.14159265359 0</pose>
      <inertial>
        <pose>0.205 0 -0.031125 0 0 0</pose>
        <mass>0.75</mass>
        <inertia>
          <ixx>0.00114219140625</ixx>
          <ixy>0</ixy>
          <ixz>0</ixz>
          <iyy>0.0107484414062</iyy>
          <iyz>0</iyz>
          <izz>0.01140625</izz>
        </inertia>
      </inertial>
      <collision name="collision">
        <pose>0.205 0 -0.031125 0 0 0</pose>
        <geometry>
          <box>
            <size>0.41 0.12 0.06225</size>
          </box>
        </geometry>
        <surface>
          <friction>
            <ode>
              <mu>0.5</mu>
              <mu2>0.5</mu2>
            </ode>
          </friction>
          <contact>
            <ode>
              <min_depth>0.01</min_depth>
            </ode>
          </contact>
        </surface>
      </collision>
      <visual name="visual">
        <pose>0.205 0 -0.031125 0 0 0</pose>
        <geometry>
          <box>
            <size>0.41 0.12 0.06225</size>
          </box>
        </geometry>
        <material>
          <ambient>0.0 0.0 0.0 1</ambient>
          <diffuse>0.0 0.0 0.0 1</diffuse>
          <specular>0.5 0.5 0.5 1</specular>
          <emissive>0 0 0 1</emissive>
        </material>
      </visual>
    </link>
  </gazebo>
  <gazebo>
    <joint name="left_crawler_track_straight_segment_joint0" type="prismatic">
      <child>left_crawler_track_straight_segment_link0</child>
      <parent>left_crawler_body</parent>
      <axis>
        <xyz>1 0 0</xyz>
        <use_parent_model_frame>0</use_parent_model_frame>
      </axis>
      <physics>
        <ode>
          <implicit_spring_damper>1</implicit_spring_damper>
        </ode>
      </physics>
    </joint>
  </gazebo>
  <gazebo>
    <joint name="left_crawler_track_straight_segment_joint1" type="prismatic">
      <child>left_crawler_track_straight_segment_link1</child>
      <parent>left_crawler_body</parent>
      <axis>
        <xyz>1 0 0</xyz>
        <use_parent_model_frame>0</use_parent_model_frame>
      </axis>
      <physics>
        <ode>
          <implicit_spring_damper>1</implicit_spring_damper>
        </ode>
      </physics>
    </joint>
  </gazebo>
  <gazebo>
    <link name="left_crawler_track_arc_segment_link0">
      <pose>0.205 0.146 0.04675 0 0 0</pose>
      <inertial>
        <pose>0 0 -0.06225 1.57079632679 0 0</pose>
        <mass>0.75</mass>
        <inertia>
          <ixx>0.00162657421875</ixx>
          <ixy>0</ixy>
          <ixz>0</ixz>
          <iyy>0.00162657421875</iyy>
          <iyz>0</iyz>
          <izz>0.0014531484375</izz>
        </inertia>
      </inertial>
      <collision name="collision">
        <pose>0 0 -0.06225 1.57079632679 0 0</pose>
        <geometry>
          <cylinder>
            <length>0.12</length>
            <radius>0.06225</radius>
          </cylinder>
        </geometry>
        <surface>
          <friction>
            <ode>
              <mu>0.5</mu>
              <mu2>0.5</mu2>
            </ode>
          </friction>
          <contact>
            <ode>
              <min_depth>0.01</min_depth>
            </ode>
          </contact>
        </surface>
      </collision>
      <visual name="visual">
        <pose>0 0 -0.06225 1.57079632679 0 0</pose>
        <geometry>
          <cylinder>
            <length>0.12</length>
            <radius>0.06225</radius>
          </cylinder>
        </geometry>
        <material>
          <ambient>0.0 0.0 0.0 1</ambient>
          <diffuse>0.0 0.0 0.0 1</diffuse>
          <specular>0.5 0.5 0.5 1</specular>
          <emissive>0 0 0 1</emissive>
        </material>
      </visual>
    </link>
  </gazebo>
  <gazebo>
    <link name="left_crawler_track_arc_segment_link1">
      <pose>-0.205 0.146 -0.07775 0 3.14159265359 0</pose>
      <inertial>
        <pose>0 0 -0.06225 1.57079632679 0 0</pose>
        <mass>0.75</mass>
        <inertia>
          <ixx>0.00162657421875</ixx>
          <ixy>0</ixy>
          <ixz>0</ixz>
          <iyy>0.00162657421875</iyy>
          <iyz>0</iyz>
          <izz>0.0014531484375</izz>
        </inertia>
      </inertial>
      <collision name="collision">
        <pose>0 0 -0.06225 1.57079632679 0 0</pose>
        <geometry>
          <cylinder>
            <length>0.12</length>
            <radius>0.06225</radius>
          </cylinder>
        </geometry>
        <surface>
          <friction>
            <ode>
              <mu>0.5</mu>
              <mu2>0.5</mu2>
            </ode>
          </friction>
          <contact>
            <ode>
              <min_depth>0.01</min_depth>
            </ode>
          </contact>
        </surface>
      </collision>
      <visual name="visual">
        <pose>0 0 -0.06225 1.57079632679 0 0</pose>
        <geometry>
          <cylinder>
            <length>0.12</length>
            <radius>0.06225</radius>
          </cylinder>
        </geometry>
        <material>
          <ambient>0.0 0.0 0.0 1</ambient>
          <diffuse>0.0 0.0 0.0 1</diffuse>
          <specular>0.5 0.5 0.5 1</specular>
          <emissive>0 0 0 1</emissive>
        </material>
      </visual>
    </link>
  </gazebo>
  <gazebo>
    <joint name="left_crawler_track_arc_segment_joint0" type="revolute">
      <child>left_crawler_track_arc_segment_link0</child>
      <parent>left_crawler_body</parent>
      <pose>0 0 -0.06225 0 0 0</pose>
      <axis>
        <xyz>0 1 0</xyz>
        <use_parent_model_frame>0</use_parent_model_frame>
      </axis>
      <physics>
        <ode>
          <implicit_spring_damper>1</implicit_spring_damper>
        </ode>
      </physics>
    </joint>
  </gazebo>
  <gazebo>
    <joint name="left_crawler_track_arc_segment_joint1" type="revolute">
      <child>left_crawler_track_arc_segment_link1</child>
      <parent>left_crawler_body</parent>
      <pose>0 0 -0.06225 0 0 0</pose>
      <axis>
        <xyz>0 1 0</xyz>
        <use_parent_model_frame>0</use_parent_model_frame>
      </axis>
      <physics>
        <ode>
          <implicit_spring_damper>1</implicit_spring_damper>
        </ode>
      </physics>
    </joint>
  </gazebo>
  <gazebo>
    <plugin filename="libContinuousTrack.so" name="left_crawler_track">
      <sprocket>
        <joint>left_crawler_sprocket_axle</joint>
        <pitch_diameter>0.1145</pitch_diameter>
      </sprocket>
      <trajectory>
        <segment>
          <joint>left_crawler_track_straight_segment_joint0</joint>
          <end_position>0.41</end_position>
        </segment>
        <segment>
          <joint>left_crawler_track_arc_segment_joint0</joint>
          <end_position>3.14159265359</end_position>
        </segment>
        <segment>
          <joint>left_crawler_track_straight_segment_joint1</joint>
          <end_position>0.41</end_position>
        </segment>
        <segment>
          <joint>left_crawler_track_arc_segment_joint1</joint>
          <end_position>3.14159265359</end_position>
        </segment>
      </trajectory>
      <pattern>
        <elements_per_round>10</elements_per_round>
        <element>
          <collision name="collision">
            <pose>0 0 0 0 0 0</pose>
            <geometry>
              <box>
                <size>0.01 0.12 0.01</size>
              </box>
            </geometry>
            <surface>
              <friction>
                <ode>
                  <mu>0.5</mu>
                  <mu2>0.5</mu2>
                </ode>
              </friction>
              <contact>
                <ode>
                  <min_depth>0.01</min_depth>
                </ode>
              </contact>
            </surface>
          </collision>
          <visual name="visual">
            <pose>0 0 0 0 0 0</pose>
            <geometry>
              <box>
                <size>0.01 0.12 0.01</size>
              </box>
            </geometry>
            <material>
              <ambient>0.0 0.0 0.0 1</ambient>
              <diffuse>0.0 0.0 0.0 1</diffuse>
              <specular>0.5 0.5 0.5 1</specular>
              <emissive>0 0 0 1</emissive>
            </material>
          </visual>
        </element>
        <element>
          <collision name="collision">
            <pose>0 0.06 0 1.57079632679 0 0</pose>
            <geometry>
              <polyline>
                <point>-0.01 -0.005</point>
                <point>-0.005 0.005</point>
                <point>0.005 0.005</point>
                <point>0.01 -0.005</point>
                <height>0.12</height>
              </polyline>
            </geometry>
            <surface>
              <friction>
                <ode>
                  <mu>0.5</mu>
                  <mu2>0.5</mu2>
                </ode>
              </friction>
              <contact>
                <ode>
                  <min_depth>0.01</min_depth>
                </ode>
              </contact>
            </surface>
          </collision>
          <visual name="visual">
            <pose>0 0.06 0 1.57079632679 0 0</pose>
            <geometry>
              <polyline>
                <point>-0.01 -0.005</point>
                <point>-0.005 0.005</point>
                <point>0.005 0.005</point>
                <point>0.01 -0.005</point>
                <height>0.12</height>
              </polyline>
            </geometry>
            <material>
              <ambient>0.0 0.0 0.0 1</ambient>
              <diffuse>0.0 0.0 0.0 1</diffuse>
              <specular>0.5 0.5 0.5 1</specular>
              <emissive>0 0 0 1</emissive>
            </material>
          </visual>
        </element>
      </pattern>
    </plugin>
  </gazebo>
  <gazebo>
    <link name="right_crawler_track_straight_segment_link0">
      <pose>-0.205 -0.146 0.04675 0 0 0</pose>
      <inertial>
        <pose>0.205 0 -0.031125 0 0 0</pose>
        <mass>0.75</mass>
        <inertia>
          <ixx>0.00114219140625</ixx>
          <ixy>0</ixy>
          <ixz>0</ixz>
          <iyy>0.0107484414062</iyy>
          <iyz>0</iyz>
          <izz>0.01140625</izz>
        </inertia>
      </inertial>
      <collision name="collision">
        <pose>0.205 0 -0.031125 0 0 0</pose>
        <geometry>
          <box>
            <size>0.41 0.12 0.06225</size>
          </box>
        </geometry>
        <surface>
          <friction>
            <ode>
              <mu>0.5</mu>
              <mu2>0.5</mu2>
            </ode>
          </friction>
          <contact>
            <ode>
              <min_depth>0.01</min_depth>
            </ode>
          </contact>
        </surface>
      </collision>
      <visual name="visual">
        <pose>0.205 0 -0.031125 0 0 0</pose>
        <geometry>
          <box>
            <size>0.41 0.12 0.06225</size>
          </box>
        </geometry>
        <material>
          <ambient>0.0 0.0 0.0 1</ambient>
          <diffuse>0.0 0.0 0.0 1</diffuse>
          <specular>0.5 0.5 0.5 1</specular>
          <emissive>0 0 0 1</emissive>
        </material>
      </visual>
    </link>
  </gazebo>
  <gazebo>
    <link name="right_crawler_track_straight_segment_link1">
      <pose>0.205 -0.146 -0.07775 0 3.14159265359 0</pose>
      <inertial>
        <pose>0.205 0 -0.031125 0 0 0</pose>
        <mass>0.75</mass>
        <inertia>
          <ixx>0.00114219140625</ixx>
          <ixy>0</ixy>
          <ixz>0</ixz>
          <iyy>0.0107484414062</iyy>
          <iyz>0</iyz>
          <izz>0.01140625</izz>
        </inertia>
      </inertial>
      <collision name="collision">
        <pose>0.205 0 -0.031125 0 0 0</pose>
        <geometry>
          <box>
            <size>0.41 0.12 0.06225</size>
          </box>
        </geometry>
        <surface>
          <friction>
            <ode>
              <mu>0.5</mu>
              <mu2>0.5</mu2>
            </ode>
          </friction>
          <contact>
            <ode>
              <min_depth>0.01</min_depth>
            </ode>
          </contact>
        </surface>
      </collision>
      <visual name="visual">
        <pose>0.205 0 -0.031125 0 0 0</pose>
        <geometry>
          <box>
            <size>0.41 0.12 0.06225</size>
          </box>
        </geometry>
        <material>
          <ambient>0.0 0.0 0.0 1</ambient>
          <diffuse>0.0 0.0 0.0 1</diffuse>
          <specular>0.5 0.5 0.5 1</specular>
          <emissive>0 0 0 1</emissive>
        </material>
      </visual>
    </link>
  </gazebo>
  <gazebo>
    <joint name="right_crawler_track_straight_segment_joint0" type="prismatic">
      <child>right_crawler_track_straight_segment_link0</child>
      <parent>right_crawler_body</parent>
      <axis>
        <xyz>1 0 0</xyz>
        <use_parent_model_frame>0</use_parent_model_frame>
      </axis>
      <physics>
        <ode>
          <implicit_spring_damper>1</implicit_spring_damper>
        </ode>
      </physics>
    </joint>
  </gazebo>
  <gazebo>
    <joint name="right_crawler_track_straight_segment_joint1" type="prismatic">
      <child>right_crawler_track_straight_segment_link1</child>
      <parent>right_crawler_body</parent>
      <axis>
        <xyz>1 0 0</xyz>
        <use_parent_model_frame>0</use_parent_model_frame>
      </axis>
      <physics>
        <ode>
          <implicit_spring_damper>1</implicit_spring_damper>
        </ode>
      </physics>
    </joint>
  </gazebo>
  <gazebo>
    <link name="right_crawler_track_arc_segment_link0">
      <pose>0.205 -0.146 0.04675 0 0 0</pose>
      <inertial>
        <pose>0 0 -0.06225 1.57079632679 0 0</pose>
        <mass>0.75</mass>
        <inertia>
          <ixx>0.00162657421875</ixx>
          <ixy>0</ixy>
          <ixz>0</ixz>
          <iyy>0.00162657421875</iyy>
          <iyz>0</iyz>
          <izz>0.0014531484375</izz>
        </inertia>
      </inertial>
      <collision name="collision">
        <pose>0 0 -0.06225 1.57079632679 0 0</pose>
        <geometry>
          <cylinder>
            <length>0.12</length>
            <radius>0.06225</radius>
          </cylinder>
        </geometry>
        <surface>
          <friction>
            <ode>
              <mu>0.5</mu>
              <mu2>0.5</mu2>
            </ode>
          </friction>
          <contact>
            <ode>
              <min_depth>0.01</min_depth>
            </ode>
          </contact>
        </surface>
      </collision>
      <visual name="visual">
        <pose>0 0 -0.06225 1.57079632679 0 0</pose>
        <geometry>
          <cylinder>
            <length>0.12</length>
            <radius>0.06225</radius>
          </cylinder>
        </geometry>
        <material>
          <ambient>0.0 0.0 0.0 1</ambient>
          <diffuse>0.0 0.0 0.0 1</diffuse>
          <specular>0.5 0.5 0.5 1</specular>
          <emissive>0 0 0 1</emissive>
        </material>
      </visual>
    </link>
  </gazebo>
  <gazebo>
    <link name="right_crawler_track_arc_segment_link1">
      <pose>-0.205 -0.146 -0.07775 0 3.14159265359 0</pose>
      <inertial>
        <pose>0 0 -0.06225 1.57079632679 0 0</pose>
        <mass>0.75</mass>
        <inertia>
          <ixx>0.00162657421875</ixx>
          <ixy>0</ixy>
          <ixz>0</ixz>
          <iyy>0.00162657421875</iyy>
          <iyz>0</iyz>
          <izz>0.0014531484375</izz>
        </inertia>
      </inertial>
      <collision name="collision">
        <pose>0 0 -0.06225 1.57079632679 0 0</pose>
        <geometry>
          <cylinder>
            <length>0.12</length>
            <radius>0.06225</radius>
          </cylinder>
        </geometry>
        <surface>
          <friction>
            <ode>
              <mu>0.5</mu>
              <mu2>0.5</mu2>
            </ode>
          </friction>
          <contact>
            <ode>
              <min_depth>0.01</min_depth>
            </ode>
          </contact>
        </surface>
      </collision>
      <visual name="visual">
        <pose>0 0 -0.06225 1.57079632679 0 0</pose>
        <geometry>
          <cylinder>
            <length>0.12</length>
            <radius>0.06225</radius>
          </cylinder>
        </geometry>
        <material>
          <ambient>0.0 0.0 0.0 1</ambient>
          <diffuse>0.0 0.0 0.0 1</diffuse>
          <specular>0.5 0.5 0.5 1</specular>
          <emissive>0 0 0 1</emissive>
        </material>
      </visual>
    </link>
  </gazebo>
  <gazebo>
    <joint name="right_crawler_track_arc_segment_joint0" type="revolute">
      <child>right_crawler_track_arc_segment_link0</child>
      <parent>right_crawler_body</parent>
      <pose>0 0 -0.06225 0 0 0</pose>
      <axis>
        <xyz>0 1 0</xyz>
        <use_parent_model_frame>0</use_parent_model_frame>
      </axis>
      <physics>
        <ode>
          <implicit_spring_damper>1</implicit_spring_damper>
        </ode>
      </physics>
    </joint>
  </gazebo>
  <gazebo>
    <joint name="right_crawler_track_arc_segment_joint1" type="revolute">
      <child>right_crawler_track_arc_segment_link1</child>
      <parent>right_crawler_body</parent>
      <pose>0 0 -0.06225 0 0 0</pose>
      <axis>
        <xyz>0 1 0</xyz>
        <use_parent_model_frame>0</use_parent_model_frame>
      </axis>
      <physics>
        <ode>
          <implicit_spring_damper>1</implicit_spring_damper>
        </ode>
      </physics>
    </joint>
  </gazebo>
  <gazebo>
    <plugin filename="libContinuousTrack.so" name="right_crawler_track">
      <sprocket>
        <joint>right_crawler_sprocket_axle</joint>
        <pitch_diameter>0.1145</pitch_diameter>
      </sprocket>
      <trajectory>
        <segment>
          <joint>right_crawler_track_straight_segment_joint0</joint>
          <end_position>0.41</end_position>
        </segment>
        <segment>
          <joint>right_crawler_track_arc_segment_joint0</joint>
          <end_position>3.14159265359</end_position>
        </segment>
        <segment>
          <joint>right_crawler_track_straight_segment_joint1</joint>
          <end_position>0.41</end_position>
        </segment>
        <segment>
          <joint>right_crawler_track_arc_segment_joint1</joint>
          <end_position>3.14159265359</end_position>
        </segment>
      </trajectory>
      <pattern>
        <elements_per_round>10</elements_per_round>
        <element>
          <collision name="collision">
            <pose>0 0 0 0 0 0</pose>
            <geometry>
              <box>
                <size>0.01 0.12 0.01</size>
              </box>
            </geometry>
            <surface>
              <friction>
                <ode>
                  <mu>0.5</mu>
                  <mu2>0.5</mu2>
                </ode>
              </friction>
              <contact>
                <ode>
                  <min_depth>0.01</min_depth>
                </ode>
              </contact>
            </surface>
          </collision>
          <visual name="visual">
            <pose>0 0 0 0 0 0</pose>
            <geometry>
              <box>
                <size>0.01 0.12 0.01</size>
              </box>
            </geometry>
            <material>
              <ambient>0.0 0.0 0.0 1</ambient>
              <diffuse>0.0 0.0 0.0 1</diffuse>
              <specular>0.5 0.5 0.5 1</specular>
              <emissive>0 0 0 1</emissive>
            </material>
          </visual>
        </element>
        <element>
          <collision name="collision">
            <pose>0 0.06 0 1.57079632679 0 0</pose>
            <geometry>
              <polyline>
                <point>-0.01 -0.005</point>
                <point>-0.005 0.005</point>
                <point>0.005 0.005</point>
                <point>0.01 -0.005</point>
                <height>0.12</height>
              </polyline>
            </geometry>
            <surface>
              <friction>
                <ode>
                  <mu>0.5</mu>
                  <mu2>0.5</mu2>
                </ode>
              </friction>
              <contact>
                <ode>
                  <min_depth>0.01</min_depth>
                </ode>
              </contact>
            </surface>
          </collision>
          <visual name="visual">
            <pose>0 0.06 0 1.57079632679 0 0</pose>
            <geometry>
              <polyline>
                <point>-0.01 -0.005</point>
                <point>-0.005 0.005</point>
                <point>0.005 0.005</point>
                <point>0.01 -0.005</point>
                <height>0.12</height>
              </polyline>
            </geometry>
            <material>
              <ambient>0.0 0.0 0.0 1</ambient>
              <diffuse>0.0 0.0 0.0 1</diffuse>
              <specular>0.5 0.5 0.5 1</specular>
              <emissive>0 0 0 1</emissive>
            </material>
          </visual>
        </element>
      </pattern>
    </plugin>
  </gazebo>
  <gazebo>
    <link name="front_left_flipper_track_straight_segment_link0">
      <pose>0.205 0.243 0.03665 0 0 0</pose>
      <inertial>
        <pose>0.114305 0 -0.026075 0 0 0</pose>
        <mass>0.75</mass>
        <inertia>
          <ixx>0.00035222640625</ixx>
          <ixy>0</ixy>
          <ixz>0</ixz>
          <iyy>0.0034363846625</iyy>
          <iyz>0</iyz>
          <izz>0.00344865825625</izz>
        </inertia>
      </inertial>
      <collision name="collision">
        <pose>0.114305 0 -0.026075 0 0 0</pose>
        <geometry>
          <box>
            <size>0.22861 0.054 0.05215</size>
          </box>
        </geometry>
        <surface>
          <friction>
            <ode>
              <mu>0.5</mu>
              <mu2>0.5</mu2>
            </ode>
          </friction>
          <contact>
            <ode>
              <min_depth>0.01</min_depth>
            </ode>
          </contact>
        </surface>
      </collision>
      <visual name="visual">
        <pose>0.114305 0 -0.026075 0 0 0</pose>
        <geometry>
          <box>
            <size>0.22861 0.054 0.05215</size>
          </box>
        </geometry>
        <material>
          <ambient>0.0 0.0 0.0 1</ambient>
          <diffuse>0.0 0.0 0.0 1</diffuse>
          <specular>0.5 0.5 0.5 1</specular>
          <emissive>0 0 0 1</emissive>
        </material>
      </visual>
    </link>
  </gazebo>
  <gazebo>
    <link name="front_left_flipper_track_straight_segment_link1">
      <pose>0.43361 0.243 -0.06765 0 3.14159265359 0</pose>
      <inertial>
        <pose>0.114305 0 -0.026075 0 0 0</pose>
        <mass>0.75</mass>
        <inertia>
          <ixx>0.00035222640625</ixx>
          <ixy>0</ixy>
          <ixz>0</ixz>
          <iyy>0.0034363846625</iyy>
          <iyz>0</iyz>
          <izz>0.00344865825625</izz>
        </inertia>
      </inertial>
      <collision name="collision">
        <pose>0.114305 0 -0.026075 0 0 0</pose>
        <geometry>
          <box>
            <size>0.22861 0.054 0.05215</size>
          </box>
        </geometry>
        <surface>
          <friction>
            <ode>
              <mu>0.5</mu>
              <mu2>0.5</mu2>
            </ode>
          </friction>
          <contact>
            <ode>
              <min_depth>0.01</min_depth>
            </ode>
          </contact>
        </surface>
      </collision>
      <visual name="visual">
        <pose>0.114305 0 -0.026075 0 0 0</pose>
        <geometry>
          <box>
            <size>0.22861 0.054 0.05215</size>
          </box>
        </geometry>
        <material>
          <ambient>0.0 0.0 0.0 1</ambient>
          <diffuse>0.0 0.0 0.0 1</diffuse>
          <specular>0.5 0.5 0.5 1</specular>
          <emissive>0 0 0 1</emissive>
        </material>
      </visual>
    </link>
  </gazebo>
  <gazebo>
    <joint name="front_left_flipper_track_straight_segment_joint0" type="prismatic">
      <child>front_left_flipper_track_straight_segment_link0</child>
      <parent>front_left_flipper_body</parent>
      <axis>
        <xyz>1 0 0</xyz>
        <use_parent_model_frame>0</use_parent_model_frame>
      </axis>
      <physics>
        <ode>
          <implicit_spring_damper>1</implicit_spring_damper>
        </ode>
      </physics>
    </joint>
  </gazebo>
  <gazebo>
    <joint name="front_left_flipper_track_straight_segment_joint1" type="prismatic">
      <child>front_left_flipper_track_straight_segment_link1</child>
      <parent>front_left_flipper_body</parent>
      <axis>
        <xyz>1 0 0</xyz>
        <use_parent_model_frame>0</use_parent_model_frame>
      </axis>
      <physics>
        <ode>
          <implicit_spring_damper>1</implicit_spring_damper>
        </ode>
      </physics>
    </joint>
  </gazebo>
  <gazebo>
    <link name="front_left_flipper_track_arc_segment_link0">
      <pose>0.43361 0.243 0.03665 0 0 0</pose>
      <inertial>
        <pose>0 0 -0.05215 1.57079632679 0 0</pose>
        <mass>0.75</mass>
        <inertia>
          <ixx>0.00069217921875</ixx>
          <ixy>0</ixy>
          <ixz>0</ixz>
          <iyy>0.00069217921875</iyy>
          <iyz>0</iyz>
          <izz>0.0010198584375</izz>
        </inertia>
      </inertial>
      <collision name="collision">
        <pose>0 0 -0.05215 1.57079632679 0 0</pose>
        <geometry>
          <cylinder>
            <length>0.054</length>
            <radius>0.05215</radius>
          </cylinder>
        </geometry>
        <surface>
          <friction>
            <ode>
              <mu>0.5</mu>
              <mu2>0.5</mu2>
            </ode>
          </friction>
          <contact>
            <ode>
              <min_depth>0.01</min_depth>
            </ode>
          </contact>
        </surface>
      </collision>
      <visual name="visual">
        <pose>0 0 -0.05215 1.57079632679 0 0</pose>
        <geometry>
          <cylinder>
            <length>0.054</length>
            <radius>0.05215</radius>
          </cylinder>
        </geometry>
        <material>
          <ambient>0.0 0.0 0.0 1</ambient>
          <diffuse>0.0 0.0 0.0 1</diffuse>
          <specular>0.5 0.5 0.5 1</specular>
          <emissive>0 0 0 1</emissive>
        </material>
      </visual>
    </link>
  </gazebo>
  <gazebo>
    <link name="front_left_flipper_track_arc_segment_link1">
      <pose>0.205 0.243 -0.06765 0 3.14159265359 0</pose>
      <inertial>
        <pose>0 0 -0.05215 1.57079632679 0 0</pose>
        <mass>0.75</mass>
        <inertia>
          <ixx>0.00069217921875</ixx>
          <ixy>0</ixy>
          <ixz>0</ixz>
          <iyy>0.00069217921875</iyy>
          <iyz>0</iyz>
          <izz>0.0010198584375</izz>
        </inertia>
      </inertial>
      <collision name="collision">
        <pose>0 0 -0.05215 1.57079632679 0 0</pose>
        <geometry>
          <cylinder>
            <length>0.054</length>
            <radius>0.05215</radius>
          </cylinder>
        </geometry>
        <surface>
          <friction>
            <ode>
              <mu>0.5</mu>
              <mu2>0.5</mu2>
            </ode>
          </friction>
          <contact>
            <ode>
              <min_depth>0.01</min_depth>
            </ode>
          </contact>
        </surface>
      </collision>
      <visual name="visual">
        <pose>0 0 -0.05215 1.57079632679 0 0</pose>
        <geometry>
          <cylinder>
            <length>0.054</length>
            <radius>0.05215</radius>
          </cylinder>
        </geometry>
        <material>
          <ambient>0.0 0.0 0.0 1</ambient>
          <diffuse>0.0 0.0 0.0 1</diffuse>
          <specular>0.5 0.5 0.5 1</specular>
          <emissive>0 0 0 1</emissive>
        </material>
      </visual>
    </link>
  </gazebo>
  <gazebo>
    <joint name="front_left_flipper_track_arc_segment_joint0" type="revolute">
      <child>front_left_flipper_track_arc_segment_link0</child>
      <parent>front_left_flipper_body</parent>
      <pose>0 0 -0.05215 0 0 0</pose>
      <axis>
        <xyz>0 1 0</xyz>
        <use_parent_model_frame>0</use_parent_model_frame>
      </axis>
      <physics>
        <ode>
          <implicit_spring_damper>1</implicit_spring_damper>
        </ode>
      </physics>
    </joint>
  </gazebo>
  <gazebo>
    <joint name="front_left_flipper_track_arc_segment_joint1" type="revolute">
      <child>front_left_flipper_track_arc_segment_link1</child>
      <parent>front_left_flipper_body</parent>
      <pose>0 0 -0.05215 0 0 0</pose>
      <axis>
        <xyz>0 1 0</xyz>
        <use_parent_model_frame>0</use_parent_model_frame>
      </axis>
      <physics>
        <ode>
          <implicit_spring_damper>1</implicit_spring_damper>
        </ode>
      </physics>
    </joint>
  </gazebo>
  <gazebo>
    <plugin filename="libContinuousTrackSimple.so" name="front_left_flipper_track">
      <sprocket>
        <joint>front_left_flipper_sprocket_axle</joint>
        <pitch_diameter>0.04215</pitch_diameter>
      </sprocket>
      <track>
        <segment>
          <joint>front_left_flipper_track_straight_segment_joint0</joint>
        </segment>
        <segment>
          <joint>front_left_flipper_track_arc_segment_joint0</joint>
          <pitch_diameter>0.04215</pitch_diameter>
        </segment>
        <segment>
          <joint>front_left_flipper_track_straight_segment_joint1</joint>
        </segment>
        <segment>
          <joint>front_left_flipper_track_arc_segment_joint1</joint>
          <pitch_diameter>0.04215</pitch_diameter>
        </segment>
      </track>
    </plugin>
  </gazebo>
  <gazebo>
    <link name="front_right_flipper_track_straight_segment_link0">
      <pose>0.205 -0.243 0.03665 0 0 0</pose>
      <inertial>
        <pose>0.114305 0 -0.026075 0 0 0</pose>
        <mass>0.75</mass>
        <inertia>
          <ixx>0.00035222640625</ixx>
          <ixy>0</ixy>
          <ixz>0</ixz>
          <iyy>0.0034363846625</iyy>
          <iyz>0</iyz>
          <izz>0.00344865825625</izz>
        </inertia>
      </inertial>
      <collision name="collision">
        <pose>0.114305 0 -0.026075 0 0 0</pose>
        <geometry>
          <box>
            <size>0.22861 0.054 0.05215</size>
          </box>
        </geometry>
        <surface>
          <friction>
            <ode>
              <mu>0.5</mu>
              <mu2>0.5</mu2>
            </ode>
          </friction>
          <contact>
            <ode>
              <min_depth>0.01</min_depth>
            </ode>
          </contact>
        </surface>
      </collision>
      <visual name="visual">
        <pose>0.114305 0 -0.026075 0 0 0</pose>
        <geometry>
          <box>
            <size>0.22861 0.054 0.05215</size>
          </box>
        </geometry>
        <material>
          <ambient>0.0 0.0 0.0 1</ambient>
          <diffuse>0.0 0.0 0.0 1</diffuse>
          <specular>0.5 0.5 0.5 1</specular>
          <emissive>0 0 0 1</emissive>
        </material>
      </visual>
    </link>
  </gazebo>
  <gazebo>
    <link name="front_right_flipper_track_straight_segment_link1">
      <pose>0.43361 -0.243 -0.06765 0 3.14159265359 0</pose>
      <inertial>
        <pose>0.114305 0 -0.026075 0 0 0</pose>
        <mass>0.75</mass>
        <inertia>
          <ixx>0.00035222640625</ixx>
          <ixy>0</ixy>
          <ixz>0</ixz>
          <iyy>0.0034363846625</iyy>
          <iyz>0</iyz>
          <izz>0.00344865825625</izz>
        </inertia>
      </inertial>
      <collision name="collision">
        <pose>0.114305 0 -0.026075 0 0 0</pose>
        <geometry>
          <box>
            <size>0.22861 0.054 0.05215</size>
          </box>
        </geometry>
        <surface>
          <friction>
            <ode>
              <mu>0.5</mu>
              <mu2>0.5</mu2>
            </ode>
          </friction>
          <contact>
            <ode>
              <min_depth>0.01</min_depth>
            </ode>
          </contact>
        </surface>
      </collision>
      <visual name="visual">
        <pose>0.114305 0 -0.026075 0 0 0</pose>
        <geometry>
          <box>
            <size>0.22861 0.054 0.05215</size>
          </box>
        </geometry>
        <material>
          <ambient>0.0 0.0 0.0 1</ambient>
          <diffuse>0.0 0.0 0.0 1</diffuse>
          <specular>0.5 0.5 0.5 1</specular>
          <emissive>0 0 0 1</emissive>
        </material>
      </visual>
    </link>
  </gazebo>
  <gazebo>
    <joint name="front_right_flipper_track_straight_segment_joint0" type="prismatic">
      <child>front_right_flipper_track_straight_segment_link0</child>
      <parent>front_right_flipper_body</parent>
      <axis>
        <xyz>1 0 0</xyz>
        <use_parent_model_frame>0</use_parent_model_frame>
      </axis>
      <physics>
        <ode>
          <implicit_spring_damper>1</implicit_spring_damper>
        </ode>
      </physics>
    </joint>
  </gazebo>
  <gazebo>
    <joint name="front_right_flipper_track_straight_segment_joint1" type="prismatic">
      <child>front_right_flipper_track_straight_segment_link1</child>
      <parent>front_right_flipper_body</parent>
      <axis>
        <xyz>1 0 0</xyz>
        <use_parent_model_frame>0</use_parent_model_frame>
      </axis>
      <physics>
        <ode>
          <implicit_spring_damper>1</implicit_spring_damper>
        </ode>
      </physics>
    </joint>
  </gazebo>
  <gazebo>
    <link name="front_right_flipper_track_arc_segment_link0">
      <pose>0.43361 -0.243 0.03665 0 0 0</pose>
      <inertial>
        <pose>0 0 -0.05215 1.57079632679 0 0</pose>
        <mass>0.75</mass>
        <inertia>
          <ixx>0.00069217921875</ixx>
          <ixy>0</ixy>
          <ixz>0</ixz>
          <iyy>0.00069217921875</iyy>
          <iyz>0</iyz>
          <izz>0.0010198584375</izz>
        </inertia>
      </inertial>
      <collision name="collision">
        <pose>0 0 -0.05215 1.57079632679 0 0</pose>
        <geometry>
          <cylinder>
            <length>0.054</length>
            <radius>0.05215</radius>
          </cylinder>
        </geometry>
        <surface>
          <friction>
            <ode>
              <mu>0.5</mu>
              <mu2>0.5</mu2>
            </ode>
          </friction>
          <contact>
            <ode>
              <min_depth>0.01</min_depth>
            </ode>
          </contact>
        </surface>
      </collision>
      <visual name="visual">
        <pose>0 0 -0.05215 1.57079632679 0 0</pose>
        <geometry>
          <cylinder>
            <length>0.054</length>
            <radius>0.05215</radius>
          </cylinder>
        </geometry>
        <material>
          <ambient>0.0 0.0 0.0 1</ambient>
          <diffuse>0.0 0.0 0.0 1</diffuse>
          <specular>0.5 0.5 0.5 1</specular>
          <emissive>0 0 0 1</emissive>
        </material>
      </visual>
    </link>
  </gazebo>
  <gazebo>
    <link name="front_right_flipper_track_arc_segment_link1">
      <pose>0.205 -0.243 -0.06765 0 3.14159265359 0</pose>
      <inertial>
        <pose>0 0 -0.05215 1.57079632679 0 0</pose>
        <mass>0.75</mass>
        <inertia>
          <ixx>0.00069217921875</ixx>
          <ixy>0</ixy>
          <ixz>0</ixz>
          <iyy>0.00069217921875</iyy>
          <iyz>0</iyz>
          <izz>0.0010198584375</izz>
        </inertia>
      </inertial>
      <collision name="collision">
        <pose>0 0 -0.05215 1.57079632679 0 0</pose>
        <geometry>
          <cylinder>
            <length>0.054</length>
            <radius>0.05215</radius>
          </cylinder>
        </geometry>
        <surface>
          <friction>
            <ode>
              <mu>0.5</mu>
              <mu2>0.5</mu2>
            </ode>
          </friction>
          <contact>
            <ode>
              <min_depth>0.01</min_depth>
            </ode>
          </contact>
        </surface>
      </collision>
      <visual name="visual">
        <pose>0 0 -0.05215 1.57079632679 0 0</pose>
        <geometry>
          <cylinder>
            <length>0.054</length>
            <radius>0.05215</radius>
          </cylinder>
        </geometry>
        <material>
          <ambient>0.0 0.0 0.0 1</ambient>
          <diffuse>0.0 0.0 0.0 1</diffuse>
          <specular>0.5 0.5 0.5 1</specular>
          <emissive>0 0 0 1</emissive>
        </material>
      </visual>
    </link>
  </gazebo>
  <gazebo>
    <joint name="front_right_flipper_track_arc_segment_joint0" type="revolute">
      <child>front_right_flipper_track_arc_segment_link0</child>
      <parent>front_right_flipper_body</parent>
      <pose>0 0 -0.05215 0 0 0</pose>
      <axis>
        <xyz>0 1 0</xyz>
        <use_parent_model_frame>0</use_parent_model_frame>
      </axis>
      <physics>
        <ode>
          <implicit_spring_damper>1</implicit_spring_damper>
        </ode>
      </physics>
    </joint>
  </gazebo>
  <gazebo>
    <joint name="front_right_flipper_track_arc_segment_joint1" type="revolute">
      <child>front_right_flipper_track_arc_segment_link1</child>
      <parent>front_right_flipper_body</parent>
      <pose>0 0 -0.05215 0 0 0</pose>
      <axis>
        <xyz>0 1 0</xyz>
        <use_parent_model_frame>0</use_parent_model_frame>
      </axis>
      <physics>
        <ode>
          <implicit_spring_damper>1</implicit_spring_damper>
        </ode>
      </physics>
    </joint>
  </gazebo>
  <gazebo>
    <plugin filename="libContinuousTrackSimple.so" name="front_right_flipper_track">
      <sprocket>
        <joint>front_right_flipper_sprocket_axle</joint>
        <pitch_diameter>0.04215</pitch_diameter>
      </sprocket>
      <track>
        <segment>
          <joint>front_right_flipper_track_straight_segment_joint0</joint>
        </segment>
        <segment>
          <joint>front_right_flipper_track_arc_segment_joint0</joint>
          <pitch_diameter>0.04215</pitch_diameter>
        </segment>
        <segment>
          <joint>front_right_flipper_track_straight_segment_joint1</joint>
        </segment>
        <segment>
          <joint>front_right_flipper_track_arc_segment_joint1</joint>
          <pitch_diameter>0.04215</pitch_diameter>
        </segment>
      </track>
    </plugin>
  </gazebo>
  <gazebo>
    <link name="rear_left_flipper_track_straight_segment_link0">
      <pose>-0.43361 0.243 0.03665 0 0 0</pose>
      <inertial>
        <pose>0.114305 0 -0.026075 0 0 0</pose>
        <mass>0.75</mass>
        <inertia>
          <ixx>0.00035222640625</ixx>
          <ixy>0</ixy>
          <ixz>0</ixz>
          <iyy>0.0034363846625</iyy>
          <iyz>0</iyz>
          <izz>0.00344865825625</izz>
        </inertia>
      </inertial>
      <collision name="collision">
        <pose>0.114305 0 -0.026075 0 0 0</pose>
        <geometry>
          <box>
            <size>0.22861 0.054 0.05215</size>
          </box>
        </geometry>
        <surface>
          <friction>
            <ode>
              <mu>0.5</mu>
              <mu2>0.5</mu2>
            </ode>
          </friction>
          <contact>
            <ode>
              <min_depth>0.01</min_depth>
            </ode>
          </contact>
        </surface>
      </collision>
      <visual name="visual">
        <pose>0.114305 0 -0.026075 0 0 0</pose>
        <geometry>
          <box>
            <size>0.22861 0.054 0.05215</size>
          </box>
        </geometry>
        <material>
          <ambient>0.0 0.0 0.0 1</ambient>
          <diffuse>0.0 0.0 0.0 1</diffuse>
          <specular>0.5 0.5 0.5 1</specular>
          <emissive>0 0 0 1</emissive>
        </material>
      </visual>
    </link>
  </gazebo>
  <gazebo>
    <link name="rear_left_flipper_track_straight_segment_link1">
      <pose>-0.205 0.243 -0.06765 0 3.14159265359 0</pose>
      <inertial>
        <pose>0.114305 0 -0.026075 0 0 0</pose>
        <mass>0.75</mass>
        <inertia>
          <ixx>0.00035222640625</ixx>
          <ixy>0</ixy>
          <ixz>0</ixz>
          <iyy>0.0034363846625</iyy>
          <iyz>0</iyz>
          <izz>0.00344865825625</izz>
        </inertia>
      </inertial>
      <collision name="collision">
        <pose>0.114305 0 -0.026075 0 0 0</pose>
        <geometry>
          <box>
            <size>0.22861 0.054 0.05215</size>
          </box>
        </geometry>
        <surface>
          <friction>
            <ode>
              <mu>0.5</mu>
              <mu2>0.5</mu2>
            </ode>
          </friction>
          <contact>
            <ode>
              <min_depth>0.01</min_depth>
            </ode>
          </contact>
        </surface>
      </collision>
      <visual name="visual">
        <pose>0.114305 0 -0.026075 0 0 0</pose>
        <geometry>
          <box>
            <size>0.22861 0.054 0.05215</size>
          </box>
        </geometry>
        <material>
          <ambient>0.0 0.0 0.0 1</ambient>
          <diffuse>0.0 0.0 0.0 1</diffuse>
          <specular>0.5 0.5 0.5 1</specular>
          <emissive>0 0 0 1</emissive>
        </material>
      </visual>
    </link>
  </gazebo>
  <gazebo>
    <joint name="rear_left_flipper_track_straight_segment_joint0" type="prismatic">
      <child>rear_left_flipper_track_straight_segment_link0</child>
      <parent>rear_left_flipper_body</parent>
      <axis>
        <xyz>1 0 0</xyz>
        <use_parent_model_frame>0</use_parent_model_frame>
      </axis>
      <physics>
        <ode>
          <implicit_spring_damper>1</implicit_spring_damper>
        </ode>
      </physics>
    </joint>
  </gazebo>
  <gazebo>
    <joint name="rear_left_flipper_track_straight_segment_joint1" type="prismatic">
      <child>rear_left_flipper_track_straight_segment_link1</child>
      <parent>rear_left_flipper_body</parent>
      <axis>
        <xyz>1 0 0</xyz>
        <use_parent_model_frame>0</use_parent_model_frame>
      </axis>
      <physics>
        <ode>
          <implicit_spring_damper>1</implicit_spring_damper>
        </ode>
      </physics>
    </joint>
  </gazebo>
  <gazebo>
    <link name="rear_left_flipper_track_arc_segment_link0">
      <pose>-0.205 0.243 0.03665 0 0 0</pose>
      <inertial>
        <pose>0 0 -0.05215 1.57079632679 0 0</pose>
        <mass>0.75</mass>
        <inertia>
          <ixx>0.00069217921875</ixx>
          <ixy>0</ixy>
          <ixz>0</ixz>
          <iyy>0.00069217921875</iyy>
          <iyz>0</iyz>
          <izz>0.0010198584375</izz>
        </inertia>
      </inertial>
      <collision name="collision">
        <pose>0 0 -0.05215 1.57079632679 0 0</pose>
        <geometry>
          <cylinder>
            <length>0.054</length>
            <radius>0.05215</radius>
          </cylinder>
        </geometry>
        <surface>
          <friction>
            <ode>
              <mu>0.5</mu>
              <mu2>0.5</mu2>
            </ode>
          </friction>
          <contact>
            <ode>
              <min_depth>0.01</min_depth>
            </ode>
          </contact>
        </surface>
      </collision>
      <visual name="visual">
        <pose>0 0 -0.05215 1.57079632679 0 0</pose>
        <geometry>
          <cylinder>
            <length>0.054</length>
            <radius>0.05215</radius>
          </cylinder>
        </geometry>
        <material>
          <ambient>0.0 0.0 0.0 1</ambient>
          <diffuse>0.0 0.0 0.0 1</diffuse>
          <specular>0.5 0.5 0.5 1</specular>
          <emissive>0 0 0 1</emissive>
        </material>
      </visual>
    </link>
  </gazebo>
  <gazebo>
    <link name="rear_left_flipper_track_arc_segment_link1">
      <pose>-0.43361 0.243 -0.06765 0 3.14159265359 0</pose>
      <inertial>
        <pose>0 0 -0.05215 1.57079632679 0 0</pose>
        <mass>0.75</mass>
        <inertia>
          <ixx>0.00069217921875</ixx>
          <ixy>0</ixy>
          <ixz>0</ixz>
          <iyy>0.00069217921875</iyy>
          <iyz>0</iyz>
          <izz>0.0010198584375</izz>
        </inertia>
      </inertial>
      <collision name="collision">
        <pose>0 0 -0.05215 1.57079632679 0 0</pose>
        <geometry>
          <cylinder>
            <length>0.054</length>
            <radius>0.05215</radius>
          </cylinder>
        </geometry>
        <surface>
          <friction>
            <ode>
              <mu>0.5</mu>
              <mu2>0.5</mu2>
            </ode>
          </friction>
          <contact>
            <ode>
              <min_depth>0.01</min_depth>
            </ode>
          </contact>
        </surface>
      </collision>
      <visual name="visual">
        <pose>0 0 -0.05215 1.57079632679 0 0</pose>
        <geometry>
          <cylinder>
            <length>0.054</length>
            <radius>0.05215</radius>
          </cylinder>
        </geometry>
        <material>
          <ambient>0.0 0.0 0.0 1</ambient>
          <diffuse>0.0 0.0 0.0 1</diffuse>
          <specular>0.5 0.5 0.5 1</specular>
          <emissive>0 0 0 1</emissive>
        </material>
      </visual>
    </link>
  </gazebo>
  <gazebo>
    <joint name="rear_left_flipper_track_arc_segment_joint0" type="revolute">
      <child>rear_left_flipper_track_arc_segment_link0</child>
      <parent>rear_left_flipper_body</parent>
      <pose>0 0 -0.05215 0 0 0</pose>
      <axis>
        <xyz>0 1 0</xyz>
        <use_parent_model_frame>0</use_parent_model_frame>
      </axis>
      <physics>
        <ode>
          <implicit_spring_damper>1</implicit_spring_damper>
        </ode>
      </physics>
    </joint>
  </gazebo>
  <gazebo>
    <joint name="rear_left_flipper_track_arc_segment_joint1" type="revolute">
      <child>rear_left_flipper_track_arc_segment_link1</child>
      <parent>rear_left_flipper_body</parent>
      <pose>0 0 -0.05215 0 0 0</pose>
      <axis>
        <xyz>0 1 0</xyz>
        <use_parent_model_frame>0</use_parent_model_frame>
      </axis>
      <physics>
        <ode>
          <implicit_spring_damper>1</implicit_spring_damper>
        </ode>
      </physics>
    </joint>
  </gazebo>
  <gazebo>
    <plugin filename="libContinuousTrackSimple.so" name="rear_left_flipper_track">
      <sprocket>
        <joint>rear_left_flipper_sprocket_axle</joint>
        <pitch_diameter>0.04215</pitch_diameter>
      </sprocket>
      <track>
        <segment>
          <joint>rear_left_flipper_track_straight_segment_joint0</joint>
        </segment>
        <segment>
          <joint>rear_left_flipper_track_arc_segment_joint0</joint>
          <pitch_diameter>0.04215</pitch_diameter>
        </segment>
        <segment>
          <joint>rear_left_flipper_track_straight_segment_joint1</joint>
        </segment>
        <segment>
          <joint>rear_left_flipper_track_arc_segment_joint1</joint>
          <pitch_diameter>0.04215</pitch_diameter>
        </segment>
      </track>
    </plugin>
  </gazebo>
  <gazebo>
    <link name="rear_right_flipper_track_straight_segment_link0">
      <pose>-0.43361 -0.243 0.03665 0 0 0</pose>
      <inertial>
        <pose>0.114305 0 -0.026075 0 0 0</pose>
        <mass>0.75</mass>
        <inertia>
          <ixx>0.00035222640625</ixx>
          <ixy>0</ixy>
          <ixz>0</ixz>
          <iyy>0.0034363846625</iyy>
          <iyz>0</iyz>
          <izz>0.00344865825625</izz>
        </inertia>
      </inertial>
      <collision name="collision">
        <pose>0.114305 0 -0.026075 0 0 0</pose>
        <geometry>
          <box>
            <size>0.22861 0.054 0.05215</size>
          </box>
        </geometry>
        <surface>
          <friction>
            <ode>
              <mu>0.5</mu>
              <mu2>0.5</mu2>
            </ode>
          </friction>
          <contact>
            <ode>
              <min_depth>0.01</min_depth>
            </ode>
          </contact>
        </surface>
      </collision>
      <visual name="visual">
        <pose>0.114305 0 -0.026075 0 0 0</pose>
        <geometry>
          <box>
            <size>0.22861 0.054 0.05215</size>
          </box>
        </geometry>
        <material>
          <ambient>0.0 0.0 0.0 1</ambient>
          <diffuse>0.0 0.0 0.0 1</diffuse>
          <specular>0.5 0.5 0.5 1</specular>
          <emissive>0 0 0 1</emissive>
        </material>
      </visual>
    </link>
  </gazebo>
  <gazebo>
    <link name="rear_right_flipper_track_straight_segment_link1">
      <pose>-0.205 -0.243 -0.06765 0 3.14159265359 0</pose>
      <inertial>
        <pose>0.114305 0 -0.026075 0 0 0</pose>
        <mass>0.75</mass>
        <inertia>
          <ixx>0.00035222640625</ixx>
          <ixy>0</ixy>
          <ixz>0</ixz>
          <iyy>0.0034363846625</iyy>
          <iyz>0</iyz>
          <izz>0.00344865825625</izz>
        </inertia>
      </inertial>
      <collision name="collision">
        <pose>0.114305 0 -0.026075 0 0 0</pose>
        <geometry>
          <box>
            <size>0.22861 0.054 0.05215</size>
          </box>
        </geometry>
        <surface>
          <friction>
            <ode>
              <mu>0.5</mu>
              <mu2>0.5</mu2>
            </ode>
          </friction>
          <contact>
            <ode>
              <min_depth>0.01</min_depth>
            </ode>
          </contact>
        </surface>
      </collision>
      <visual name="visual">
        <pose>0.114305 0 -0.026075 0 0 0</pose>
        <geometry>
          <box>
            <size>0.22861 0.054 0.05215</size>
          </box>
        </geometry>
        <material>
          <ambient>0.0 0.0 0.0 1</ambient>
          <diffuse>0.0 0.0 0.0 1</diffuse>
          <specular>0.5 0.5 0.5 1</specular>
          <emissive>0 0 0 1</emissive>
        </material>
      </visual>
    </link>
  </gazebo>
  <gazebo>
    <joint name="rear_right_flipper_track_straight_segment_joint0" type="prismatic">
      <child>rear_right_flipper_track_straight_segment_link0</child>
      <parent>rear_right_flipper_body</parent>
      <axis>
        <xyz>1 0 0</xyz>
        <use_parent_model_frame>0</use_parent_model_frame>
      </axis>
      <physics>
        <ode>
          <implicit_spring_damper>1</implicit_spring_damper>
        </ode>
      </physics>
    </joint>
  </gazebo>
  <gazebo>
    <joint name="rear_right_flipper_track_straight_segment_joint1" type="prismatic">
      <child>rear_right_flipper_track_straight_segment_link1</child>
      <parent>rear_right_flipper_body</parent>
      <axis>
        <xyz>1 0 0</xyz>
        <use_parent_model_frame>0</use_parent_model_frame>
      </axis>
      <physics>
        <ode>
          <implicit_spring_damper>1</implicit_spring_damper>
        </ode>
      </physics>
    </joint>
  </gazebo>
  <gazebo>
    <link name="rear_right_flipper_track_arc_segment_link0">
      <pose>-0.205 -0.243 0.03665 0 0 0</pose>
      <inertial>
        <pose>0 0 -0.05215 1.57079632679 0 0</pose>
        <mass>0.75</mass>
        <inertia>
          <ixx>0.00069217921875</ixx>
          <ixy>0</ixy>
          <ixz>0</ixz>
          <iyy>0.00069217921875</iyy>
          <iyz>0</iyz>
          <izz>0.0010198584375</izz>
        </inertia>
      </inertial>
      <collision name="collision">
        <pose>0 0 -0.05215 1.57079632679 0 0</pose>
        <geometry>
          <cylinder>
            <length>0.054</length>
            <radius>0.05215</radius>
          </cylinder>
        </geometry>
        <surface>
          <friction>
            <ode>
              <mu>0.5</mu>
              <mu2>0.5</mu2>
            </ode>
          </friction>
          <contact>
            <ode>
              <min_depth>0.01</min_depth>
            </ode>
          </contact>
        </surface>
      </collision>
      <visual name="visual">
        <pose>0 0 -0.05215 1.57079632679 0 0</pose>
        <geometry>
          <cylinder>
            <length>0.054</length>
            <radius>0.05215</radius>
          </cylinder>
        </geometry>
        <material>
          <ambient>0.0 0.0 0.0 1</ambient>
          <diffuse>0.0 0.0 0.0 1</diffuse>
          <specular>0.5 0.5 0.5 1</specular>
          <emissive>0 0 0 1</emissive>
        </material>
      </visual>
    </link>
  </gazebo>
  <gazebo>
    <link name="rear_right_flipper_track_arc_segment_link1">
      <pose>-0.43361 -0.243 -0.06765 0 3.14159265359 0</pose>
      <inertial>
        <pose>0 0 -0.05215 1.57079632679 0 0</pose>
        <mass>0.75</mass>
        <inertia>
          <ixx>0.00069217921875</ixx>
          <ixy>0</ixy>
          <ixz>0</ixz>
          <iyy>0.00069217921875</iyy>
          <iyz>0</iyz>
          <izz>0.0010198584375</izz>
        </inertia>
      </inertial>
      <collision name="collision">
        <pose>0 0 -0.05215 1.57079632679 0 0</pose>
        <geometry>
          <cylinder>
            <length>0.054</length>
            <radius>0.05215</radius>
          </cylinder>
        </geometry>
        <surface>
          <friction>
            <ode>
              <mu>0.5</mu>
              <mu2>0.5</mu2>
            </ode>
          </friction>
          <contact>
            <ode>
              <min_depth>0.01</min_depth>
            </ode>
          </contact>
        </surface>
      </collision>
      <visual name="visual">
        <pose>0 0 -0.05215 1.57079632679 0 0</pose>
        <geometry>
          <cylinder>
            <length>0.054</length>
            <radius>0.05215</radius>
          </cylinder>
        </geometry>
        <material>
          <ambient>0.0 0.0 0.0 1</ambient>
          <diffuse>0.0 0.0 0.0 1</diffuse>
          <specular>0.5 0.5 0.5 1</specular>
          <emissive>0 0 0 1</emissive>
        </material>
      </visual>
    </link>
  </gazebo>
  <gazebo>
    <joint name="rear_right_flipper_track_arc_segment_joint0" type="revolute">
      <child>rear_right_flipper_track_arc_segment_link0</child>
      <parent>rear_right_flipper_body</parent>
      <pose>0 0 -0.05215 0 0 0</pose>
      <axis>
        <xyz>0 1 0</xyz>
        <use_parent_model_frame>0</use_parent_model_frame>
      </axis>
      <physics>
        <ode>
          <implicit_spring_damper>1</implicit_spring_damper>
        </ode>
      </physics>
    </joint>
  </gazebo>
  <gazebo>
    <joint name="rear_right_flipper_track_arc_segment_joint1" type="revolute">
      <child>rear_right_flipper_track_arc_segment_link1</child>
      <parent>rear_right_flipper_body</parent>
      <pose>0 0 -0.05215 0 0 0</pose>
      <axis>
        <xyz>0 1 0</xyz>
        <use_parent_model_frame>0</use_parent_model_frame>
      </axis>
      <physics>
        <ode>
          <implicit_spring_damper>1</implicit_spring_damper>
        </ode>
      </physics>
    </joint>
  </gazebo>
  <gazebo>
    <plugin filename="libContinuousTrackSimple.so" name="rear_right_flipper_track">
      <sprocket>
        <joint>rear_right_flipper_sprocket_axle</joint>
        <pitch_diameter>0.04215</pitch_diameter>
      </sprocket>
      <track>
        <segment>
          <joint>rear_right_flipper_track_straight_segment_joint0</joint>
        </segment>
        <segment>
          <joint>rear_right_flipper_track_arc_segment_joint0</joint>
          <pitch_diameter>0.04215</pitch_diameter>
        </segment>
        <segment>
          <joint>rear_right_flipper_track_straight_segment_joint1</joint>
        </segment>
        <segment>
          <joint>rear_right_flipper_track_arc_segment_joint1</joint>
          <pitch_diameter>0.04215</pitch_diameter>
        </segment>
      </track>
    </plugin>
  </gazebo>
  <!-- ros_control for gazebo -->
  <gazebo>
    <plugin filename="libgazebo_ros_control.so" name="gazebo_ros_control">
      <robotSimType>gazebo_ros_control/DefaultRobotHWSim</robotSimType>
      <legacyModeNS>false</legacyModeNS>
    </plugin>
  </gazebo>
</robot>
